something wrong in page13
category=體育
title=NBA》戰鬥力爆棚 詹姆斯俾倪群雄
site_url=http://www.chinatimes.com/realtimenews/20180508001878-260403
Traceback (most recent call last):
  File "C:\Users\MCU\AppData\Local\Programs\Python\Python35\lib\site-packages\urllib3\connection.py", line 141, in _new_conn
    (self.host, self.port), self.timeout, **extra_kw)
  File "C:\Users\MCU\AppData\Local\Programs\Python\Python35\lib\site-packages\urllib3\util\connection.py", line 83, in create_connection
    raise err
  File "C:\Users\MCU\AppData\Local\Programs\Python\Python35\lib\site-packages\urllib3\util\connection.py", line 73, in create_connection
    sock.connect(sa)
TimeoutError: [WinError 10060] 連線嘗試失敗，因為連線對象有一段時間並未正確回應，或是連線建立失敗，因為連線的主機無法回應。

During handling of the above exception, another exception occurred:

Traceback (most recent call last):
  File "C:\Users\MCU\AppData\Local\Programs\Python\Python35\lib\site-packages\urllib3\connectionpool.py", line 601, in urlopen
    chunked=chunked)
  File "C:\Users\MCU\AppData\Local\Programs\Python\Python35\lib\site-packages\urllib3\connectionpool.py", line 357, in _make_request
    conn.request(method, url, **httplib_request_kw)
  File "C:\Users\MCU\AppData\Local\Programs\Python\Python35\lib\http\client.py", line 1107, in request
    self._send_request(method, url, body, headers)
  File "C:\Users\MCU\AppData\Local\Programs\Python\Python35\lib\http\client.py", line 1152, in _send_request
    self.endheaders(body)
  File "C:\Users\MCU\AppData\Local\Programs\Python\Python35\lib\http\client.py", line 1103, in endheaders
    self._send_output(message_body)
  File "C:\Users\MCU\AppData\Local\Programs\Python\Python35\lib\http\client.py", line 934, in _send_output
    self.send(msg)
  File "C:\Users\MCU\AppData\Local\Programs\Python\Python35\lib\http\client.py", line 877, in send
    self.connect()
  File "C:\Users\MCU\AppData\Local\Programs\Python\Python35\lib\site-packages\urllib3\connection.py", line 166, in connect
    conn = self._new_conn()
  File "C:\Users\MCU\AppData\Local\Programs\Python\Python35\lib\site-packages\urllib3\connection.py", line 150, in _new_conn
    self, "Failed to establish a new connection: %s" % e)
urllib3.exceptions.NewConnectionError: <urllib3.connection.HTTPConnection object at 0x0000020D54B217B8>: Failed to establish a new connection: [WinError 10060] 連線嘗試失敗，因為連線對象有一段時間並未正確回應，或是連線建立失敗，因為連線的主機無法回應。

During handling of the above exception, another exception occurred:

Traceback (most recent call last):
  File "C:\Users\MCU\AppData\Local\Programs\Python\Python35\lib\site-packages\requests\adapters.py", line 440, in send
    timeout=timeout
  File "C:\Users\MCU\AppData\Local\Programs\Python\Python35\lib\site-packages\urllib3\connectionpool.py", line 639, in urlopen
    _stacktrace=sys.exc_info()[2])
  File "C:\Users\MCU\AppData\Local\Programs\Python\Python35\lib\site-packages\urllib3\util\retry.py", line 388, in increment
    raise MaxRetryError(_pool, url, error or ResponseError(cause))
urllib3.exceptions.MaxRetryError: HTTPConnectionPool(host='www.chinatimes.com', port=80): Max retries exceeded with url: /realtimenews/20180508001878-260403 (Caused by NewConnectionError('<urllib3.connection.HTTPConnection object at 0x0000020D54B217B8>: Failed to establish a new connection: [WinError 10060] 連線嘗試失敗，因為連線對象有一段時間並未正確回應，或是連線建立失敗，因為連線的主機無法回應。',))

During handling of the above exception, another exception occurred:

Traceback (most recent call last):
  File "C:\Users\MCU\Desktop\crawler\ChinatimesCrawler.py", line 82, in <module>
    result = req.get(site_url).text
  File "C:\Users\MCU\AppData\Local\Programs\Python\Python35\lib\site-packages\requests\api.py", line 72, in get
    return request('get', url, params=params, **kwargs)
  File "C:\Users\MCU\AppData\Local\Programs\Python\Python35\lib\site-packages\requests\api.py", line 58, in request
    return session.request(method=method, url=url, **kwargs)
  File "C:\Users\MCU\AppData\Local\Programs\Python\Python35\lib\site-packages\requests\sessions.py", line 508, in request
    resp = self.send(prep, **send_kwargs)
  File "C:\Users\MCU\AppData\Local\Programs\Python\Python35\lib\site-packages\requests\sessions.py", line 618, in send
    r = adapter.send(request, **kwargs)
  File "C:\Users\MCU\AppData\Local\Programs\Python\Python35\lib\site-packages\requests\adapters.py", line 508, in send
    raise ConnectionError(e, request=request)
requests.exceptions.ConnectionError: HTTPConnectionPool(host='www.chinatimes.com', port=80): Max retries exceeded with url: /realtimenews/20180508001878-260403 (Caused by NewConnectionError('<urllib3.connection.HTTPConnection object at 0x0000020D54B217B8>: Failed to establish a new connection: [WinError 10060] 連線嘗試失敗，因為連線對象有一段時間並未正確回應，或是連線建立失敗，因為連線的主機無法回應。',))

